<mujoco model="H1031">
  <compiler angle="radian" meshdir="meshes/"/>

  <asset>
    <mesh name="pelvis" content_type="model/stl" file="pelvis.stl"/>
    <mesh name="pelvis_collision_link" content_type="model/stl" file="pelvis_collision.stl"/>
    <mesh name="left_hip_pitch_link" content_type="model/stl" file="left_hip_pitch_link.stl"/>
    <mesh name="left_hip_roll_link" content_type="model/stl" file="left_hip_roll_link.stl"/>
    <mesh name="left_hip_yaw_link" content_type="model/stl" file="left_hip_yaw_link.stl"/>
    <mesh name="left_knee_link" content_type="model/stl" file="left_knee_link.stl"/>
    <mesh name="left_ankle_roll_link" content_type="model/stl" file="left_ankle_roll_link.stl"/>
    <mesh name="left_ankle_pitch_link" content_type="model/stl" file="left_ankle_pitch_link.stl"/>
    <mesh name="right_hip_pitch_link" content_type="model/stl" file="right_hip_pitch_link.stl"/>
    <mesh name="right_hip_roll_link" content_type="model/stl" file="right_hip_roll_link.stl"/>
    <mesh name="right_hip_yaw_link" content_type="model/stl" file="right_hip_yaw_link.stl"/>
    <mesh name="right_knee_link" content_type="model/stl" file="right_knee_link.stl"/>
    <mesh name="right_ankle_roll_link" content_type="model/stl" file="right_ankle_roll_link.stl"/>
    <mesh name="right_ankle_pitch_link" content_type="model/stl" file="right_ankle_pitch_link.stl"/>
    <mesh name="waist_yaw_link" content_type="model/stl" file="waist_yaw_link.stl"/>
    <mesh name="waist_roll_link" content_type="model/stl" file="waist_roll_link.stl"/>
    <mesh name="torso_link" content_type="model/stl" file="torso_link.stl"/>
    <mesh name="torso_collision" content_type="model/stl" file="torso_collision.stl"/>
    <mesh name="head_pitch_link" content_type="model/stl" file="head_pitch_link.stl"/>
    <mesh name="head_yaw_link" content_type="model/stl" file="head_yaw_link.stl"/>
    <mesh name="left_shoulder_pitch_link" content_type="model/stl" file="left_shoulder_pitch_link.stl"/>
    <mesh name="left_shoulder_roll_link" content_type="model/stl" file="left_shoulder_roll_link.stl"/>
    <mesh name="left_shoulder_yaw_link" content_type="model/stl" file="left_shoulder_yaw_link.stl"/>
    <mesh name="left_elbow_link" content_type="model/stl" file="left_elbow_link.stl"/>
    <mesh name="left_wrist_roll_link" content_type="model/stl" file="left_wrist_roll_link.stl"/>
    <mesh name="left_wrist_pitch_link" content_type="model/stl" file="left_wrist_pitch_link.stl"/>
    <mesh name="left_rubber_hand" content_type="model/stl" file="left_rubber_hand.stl"/>
    <mesh name="right_shoulder_pitch_link" content_type="model/stl" file="right_shoulder_pitch_link.stl"/>
    <mesh name="right_shoulder_roll_link" content_type="model/stl" file="right_shoulder_roll_link.stl"/>
    <mesh name="right_shoulder_yaw_link" content_type="model/stl" file="right_shoulder_yaw_link.stl"/>
    <mesh name="right_elbow_link" content_type="model/stl" file="right_elbow_link.stl"/>
    <mesh name="right_wrist_roll_link" content_type="model/stl" file="right_wrist_roll_link.stl"/>
    <mesh name="right_wrist_pitch_link" content_type="model/stl" file="right_wrist_pitch_link.stl"/>
    <mesh name="right_rubber_hand" content_type="model/stl" file="right_rubber_hand.stl"/>
  </asset>

  <worldbody>
    <body name="pelvis" pos="0 0 1.04">
      <site name="imu" size="0.01" pos="0.0 0.0 0.0"/>
      <inertial pos="0.00046244 -0.00004214 -0.01473435" quat="1 0 0 0" mass="7.60468095" diaginertia="0.03548205 0.02290677 0.02753519"/>
      <joint name="floating_base_joint" type="free" limited="false" actuatorfrclimited="false"/>
      <geom type="mesh" contype="0" conaffinity="0" group="1" density="0" rgba="0.2 0.2 0.2 1" mesh="pelvis"/>
      <geom type="mesh" contype="0" conaffinity="0" group="1" density="0" rgba="0.7 0.7 0.7 1" mesh="pelvis_collision_link"/>
      <geom type="mesh" rgba="0.7 0.7 0.7 1" mesh="pelvis_collision_link"/>
      <body name="left_hip_pitch_link" pos="0 0.083873 -0.048424" quat="0.965926 -0.25882 0 0">
        <inertial pos="0.00300595 0.0593147 -0.0170915" quat="0.899485 0.435934 -0.0222136 -0.0198741" mass="2.79753" diaginertia="0.00510297 0.00410085 0.0034593"/>
        <joint name="left_hip_pitch_joint" pos="0 0 0" axis="0 1 0" range="-2.4526 2.77542" actuatorfrcrange="-360 360"/>
        <geom type="mesh" contype="0" conaffinity="0" group="1" density="0" rgba="0.7 0.7 0.7 1" mesh="left_hip_pitch_link"/>
        <geom type="mesh" rgba="0.7 0.7 0.7 1" mesh="left_hip_pitch_link"/>
        <body name="left_hip_roll_link" pos="0.041851 0.0635 -0.019" quat="0.965926 0.25882 0 0">
          <inertial pos="-0.0302619 -0.0046893 -0.0444985" quat="-0.0935812 0.633472 -0.0477755 0.766598" mass="0.627146" diaginertia="0.00200252 0.00167509 0.00128023"/>
          <joint name="left_hip_roll_joint" pos="0 0 0" axis="1 0 0" range="-0.467441 2.16886" actuatorfrcrange="-360 360"/>
          <geom type="mesh" contype="0" conaffinity="0" group="1" density="0" rgba="0.7 0.7 0.7 1" mesh="left_hip_roll_link"/>
          <geom type="mesh" rgba="0.7 0.7 0.7 1" mesh="left_hip_roll_link"/>
          <body name="left_hip_yaw_link" pos="-0.028187 -0.0095 -0.073">
            <inertial pos="0.00069408 -0.0108659 -0.113015" quat="0.621993 -0.0405952 0.0198637 0.781717" mass="7.08752" diaginertia="0.0514012 0.050596 0.0130067"/>
            <joint name="left_hip_yaw_joint" pos="0 0 0" axis="0 0 1" range="-2.827 2.827" actuatorfrcrange="-360 360"/>
            <geom type="mesh" contype="0" conaffinity="0" group="1" density="0" rgba="0.7 0.7 0.7 1" mesh="left_hip_yaw_link"/>
            <geom type="mesh" rgba="0.7 0.7 0.7 1" mesh="left_hip_yaw_link"/>
            <body name="left_knee_link" pos="-0.010341 0.018489 -0.3191">
              <inertial pos="0.00461331 -0.0245322 -0.167155" quat="0.689662 0.00325283 0.00290593 0.724118" mass="3.5534" diaginertia="0.0512388 0.0510884 0.00333998"/>
              <joint name="left_knee_joint" pos="0 0 0" axis="0 1 0" range="-0.08725 2.53025" actuatorfrcrange="-360 360"/>
              <geom type="mesh" contype="0" conaffinity="0" group="1" density="0" rgba="0.7 0.7 0.7 1" mesh="left_knee_link"/>
              <geom size="0.04 0.175" pos="0.01 -0.025 -0.25" type="cylinder" rgba="0.7 0.7 0.7 1"/>
              <body name="left_ankle_roll_link" pos="0.03272 -0.023002 -0.49662">
                <inertial pos="-0.0174063 6.424e-05 -0.0002146" quat="0.499157 0.502573 -0.497809 0.500449" mass="0.123182" diaginertia="4.00501e-05 3.43207e-05 1.44993e-05"/>
                <joint name="left_ankle_roll_joint" pos="0 0 0" axis="1 0 0" range="-0.349066 0.296706" actuatorfrcrange="-19 19"/>
                <geom type="mesh" contype="0" conaffinity="0" group="1" density="0" rgba="0.7 0.7 0.7 1" mesh="left_ankle_roll_link"/>
                <body name="left_ankle_pitch_link" pos="-0.0225 -0.0373 0">
                  <inertial pos="0.032059 0.0370053 -0.0288282" quat="6.19452e-05 0.72345 -3.0004e-05 0.690377" mass="0.844967" diaginertia="0.00438317 0.00410964 0.000599978"/>
                  <joint name="left_ankle_pitch_joint" pos="0 0 0" axis="0 1 0" range="-1.13446 0.610865" actuatorfrcrange="-66.88 66.88"/>
                  <geom type="mesh" contype="0" conaffinity="0" group="1" density="0" rgba="0.4 0.4 0.4 1" mesh="left_ankle_pitch_link"/>
                  <geom type="mesh" rgba="0.4 0.4 0.4 1" mesh="left_ankle_pitch_link"/>
                </body>
              </body>
            </body>
          </body>
        </body>
      </body>
      <body name="right_hip_pitch_link" pos="0 -0.083873 -0.048424" quat="0.965926 0.25882 0 0">
        <inertial pos="0.00300595 -0.0593147 -0.0170915" quat="0.435934 0.899485 0.0198741 0.0222136" mass="2.79753" diaginertia="0.00510297 0.00410085 0.0034593"/>
        <joint name="right_hip_pitch_joint" pos="0 0 0" axis="0 1 0" range="-2.4526 2.77542" actuatorfrcrange="-360 360"/>
        <geom type="mesh" contype="0" conaffinity="0" group="1" density="0" rgba="0.7 0.7 0.7 1" mesh="right_hip_pitch_link"/>
        <geom type="mesh" rgba="0.7 0.7 0.7 1" mesh="right_hip_pitch_link"/>
        <body name="right_hip_roll_link" pos="0.041851 -0.0635 -0.019" quat="0.965926 -0.25882 0 0">
          <inertial pos="-0.0302619 0.0046893 -0.0444985" quat="0.0935812 0.633472 0.0477755 0.766598" mass="0.627146" diaginertia="0.00200252 0.00167509 0.00128023"/>
          <joint name="right_hip_roll_joint" pos="0 0 0" axis="1 0 0" range="-2.16886 0.467441" actuatorfrcrange="-360 360"/>
          <geom type="mesh" contype="0" conaffinity="0" group="1" density="0" rgba="0.7 0.7 0.7 1" mesh="right_hip_roll_link"/>
          <geom type="mesh" rgba="0.7 0.7 0.7 1" mesh="right_hip_roll_link"/>
          <body name="right_hip_yaw_link" pos="-0.028187 0.0095 -0.073">
            <inertial pos="0.00069408 0.0108659 -0.113015" quat="0.781717 0.0198637 -0.0405952 0.621993" mass="7.08752" diaginertia="0.0514012 0.050596 0.0130067"/>
            <joint name="right_hip_yaw_joint" pos="0 0 0" axis="0 0 1" range="-2.827 2.827" actuatorfrcrange="-360 360"/>
            <geom type="mesh" contype="0" conaffinity="0" group="1" density="0" rgba="0.7 0.7 0.7 1" mesh="right_hip_yaw_link"/>
            <geom type="mesh" rgba="0.7 0.7 0.7 1" mesh="right_hip_yaw_link"/>
            <body name="right_knee_link" pos="-0.010341 -0.018489 -0.3191">
              <inertial pos="0.00461331 0.0245322 -0.167155" quat="0.724118 0.00290593 0.00325283 0.689662" mass="3.5534" diaginertia="0.0512388 0.0510884 0.00333998"/>
              <joint name="right_knee_joint" pos="0 0 0" axis="0 1 0" range="-0.08725 2.53025" actuatorfrcrange="-360 360"/>
              <geom type="mesh" contype="0" conaffinity="0" group="1" density="0" rgba="0.7 0.7 0.7 1" mesh="right_knee_link"/>
              <geom size="0.04 0.175" pos="0.01 0.025 -0.25" type="cylinder" rgba="0.7 0.7 0.7 1"/>
              <body name="right_ankle_roll_link" pos="0.03272 0.023002 -0.49662">
                <inertial pos="-0.0174063 -6.424e-05 -0.0002146" quat="0.502573 0.499157 -0.500449 0.497809" mass="0.123182" diaginertia="4.00501e-05 3.43207e-05 1.44993e-05"/>
                <joint name="right_ankle_roll_joint" pos="0 0 0" axis="1 0 0" range="-0.296706 0.349066" actuatorfrcrange="-19 19"/>
                <geom type="mesh" contype="0" conaffinity="0" group="1" density="0" rgba="0.7 0.7 0.7 1" mesh="right_ankle_roll_link"/>
                <body name="right_ankle_pitch_link" pos="-0.0225 0.0373 0">
                  <inertial pos="0.032059 -0.0370053 -0.0288282" quat="-6.19452e-05 0.72345 3.0004e-05 0.690377" mass="0.844967" diaginertia="0.00438317 0.00410964 0.000599978"/>
                  <joint name="right_ankle_pitch_joint" pos="0 0 0" axis="0 1 0" range="-1.13446 0.610865" actuatorfrcrange="-66.88 66.88"/>
                  <geom type="mesh" contype="0" conaffinity="0" group="1" density="0" rgba="0.4 0.4 0.4 1" mesh="right_ankle_pitch_link"/>
                  <geom type="mesh" rgba="0.4 0.4 0.4 1" mesh="right_ankle_pitch_link"/>
                </body>
              </body>
            </body>
          </body>
        </body>
      </body>
      <body name="waist_yaw_link" pos="0 0 0.089837">
        <inertial pos="0.00626994 0 0.0169696" quat="0 0.717728 0 0.696323" mass="0.279762" diaginertia="0.000311422 0.0002473 0.000123348"/>
        <joint name="waist_yaw_joint" pos="0 0 0" axis="0 0 1" range="-1.7453 1.7453" actuatorfrcrange="-120 120"/>
        <geom type="mesh" contype="0" conaffinity="0" group="1" density="0" rgba="0.7 0.7 0.7 1" mesh="waist_yaw_link"/>
        <body name="waist_roll_link">
          <inertial pos="0 0.00128474 0" quat="0 0.707107 0 0.707107" mass="0.0658504" diaginertia="1.58e-05 1.041e-05 8.09e-06"/>
          <joint name="waist_roll_joint" pos="0 0 0" axis="1 0 0" range="-0.5236 0.5236" actuatorfrcrange="-180 180"/>
          <geom type="mesh" contype="0" conaffinity="0" group="1" density="0" rgba="0.7 0.7 0.7 1" mesh="waist_roll_link"/>
          <body name="torso_link">
            <inertial pos="0.0134247 0.0054719 0.210501" quat="0.999399 -0.0341887 0.00399831 0.00403179" mass="15.8703" diaginertia="0.273064 0.244383 0.0840858"/>
            <joint name="waist_pitch_joint" pos="0 0 0" axis="0 1 0" range="-0.43633 0.5236" actuatorfrcrange="-180 180"/>
            <geom type="mesh" contype="0" conaffinity="0" group="1" density="0" rgba="0.4 0.4 0.4 1" mesh="torso_link"/>
            <geom type="mesh" rgba="0.4 0.4 0.4 1" mesh="torso_collision"/>
            <body name="head_pitch_link" pos="-0.0002283 2.7112e-05 0.42181">
              <inertial pos="5.279e-08 -0.00035318 0.045125" quat="0.999996 -0.000955249 -0.00262397 -0.000580497" mass="1.82" diaginertia="0.00538697 0.00532442 0.00140982"/>
              <joint name="head_pitch_joint" pos="0 0 0" axis="0 1 0" range="-0.5236 0.83775" actuatorfrcrange="-50 50"/>
              <geom type="mesh" contype="0" conaffinity="0" group="1" density="0" rgba="0.7 0.7 0.7 1" mesh="head_pitch_link"/>
              <body name="head_yaw_link" pos="0 0.0003 0.1325">
                <inertial pos="0.0219 0 0.0187" quat="0.667311 -0.227767 -0.231751 0.670156" mass="1.3" diaginertia="0.00535274 0.00472336 0.00378091"/>
                <joint name="head_yaw_joint" pos="0 0 0" axis="0 0 1" range="-1.7453 1.7453" actuatorfrcrange="-50 50"/>
                <geom type="mesh" contype="0" conaffinity="0" group="1" density="0" rgba="0.7 0.7 0.7 1" mesh="head_yaw_link"/>
                <geom type="mesh" rgba="0.7 0.7 0.7 1" mesh="head_yaw_link"/>
              </body>
            </body>
            <body name="left_shoulder_pitch_link" pos="0.0015 0.11254 0.35812" quat="0.990959 0.134164 0 0">
              <inertial pos="0.00296153 0.0520268 -0.025045" quat="0.955852 0.29138 -0.0379121 0.00288293" mass="1.06056" diaginertia="0.00122192 0.00110581 0.000458834"/>
              <joint name="left_shoulder_pitch_joint" pos="0 0 0" axis="0 1 0" range="-2.61799 1.8326" actuatorfrcrange="-120 120"/>
              <geom type="mesh" contype="0" conaffinity="0" group="1" density="0" rgba="0.7 0.7 0.7 1" mesh="left_shoulder_pitch_link"/>
              <geom type="mesh" rgba="0.7 0.7 0.7 1" mesh="left_shoulder_pitch_link"/>
              <body name="left_shoulder_roll_link" pos="0.027682 0.061638 -0.039909" quat="0.990959 -0.134164 0 0">
                <inertial pos="-0.02061 0.00415443 -0.0629422" quat="0.678366 0.110828 0.0778018 0.722138" mass="1.34511" diaginertia="0.00210225 0.00198513 0.00105666"/>
                <joint name="left_shoulder_roll_joint" pos="0 0 0" axis="1 0 0" range="-0.516617 2.63545" actuatorfrcrange="-54 54"/>
                <geom type="mesh" contype="0" conaffinity="0" group="1" density="0" rgba="0.7 0.7 0.7 1" mesh="left_shoulder_roll_link"/>
                <geom type="mesh" rgba="0.7 0.7 0.7 1" mesh="left_shoulder_roll_link"/>
                <body name="left_shoulder_yaw_link" pos="-0.030632 0.0037809 -0.10422">
                  <inertial pos="0.00364187 0.0186515 -0.0558555" quat="0.995617 -0.0729116 -0.0584518 -0.00371547" mass="0.915717" diaginertia="0.00306267 0.00257349 0.00143042"/>
                  <joint name="left_shoulder_yaw_joint" pos="0 0 0" axis="0 0 1" range="-2.61799 2.61799" actuatorfrcrange="-54 54"/>
                  <geom type="mesh" contype="0" conaffinity="0" group="1" density="0" rgba="0.7 0.7 0.7 1" mesh="left_shoulder_yaw_link"/>
                  <geom type="mesh" rgba="0.7 0.7 0.7 1" mesh="left_shoulder_yaw_link"/>
                  <body name="left_elbow_link" pos="0.016955 0.031006 -0.12719">
                    <inertial pos="0.0459969 -0.0283296 -0.00661325" quat="0.520177 0.507229 0.507638 0.463074" mass="1.69432" diaginertia="0.00548751 0.00533836 0.000695052"/>
                    <joint name="left_elbow_joint" pos="0 0 0" axis="0 1 0" range="-0.986111 3.07178" actuatorfrcrange="-54 54"/>
                    <geom type="mesh" contype="0" conaffinity="0" group="1" density="0" rgba="0.7 0.7 0.7 1" mesh="left_elbow_link"/>
                    <geom type="mesh" rgba="0.7 0.7 0.7 1" mesh="left_elbow_link"/>
                    <body name="left_wrist_roll_link" pos="0.12826 -0.030815 -0.013299">
                      <inertial pos="0.0337195 0.00237482 0.00031544" quat="-0.242945 0.638599 0.286806 0.671499" mass="0.969837" diaginertia="0.000926999 0.000903832 0.000852829"/>
                      <joint name="left_wrist_roll_joint" pos="0 0 0" axis="1 0 0" range="-2.61799 2.61799" actuatorfrcrange="-54 54"/>
                      <geom type="mesh" contype="0" conaffinity="0" group="1" density="0" rgba="0.7 0.7 0.7 1" mesh="left_wrist_roll_link"/>
                      <body name="left_wrist_pitch_link" pos="0.082003 -0.031003 0.00020786">
                        <inertial pos="0.01821 0.0314035 0.0115687" quat="0.977698 -0.037912 -0.203807 0.033629" mass="0.946953" diaginertia="0.000918192 0.00082104 0.000648419"/>
                        <joint name="left_wrist_pitch_joint" pos="0 0 0" axis="0 1 0" range="-0.436332 0.436332" actuatorfrcrange="-25 25"/>
                        <geom type="mesh" contype="0" conaffinity="0" group="1" density="0" rgba="0.7 0.7 0.7 1" mesh="left_wrist_pitch_link"/>
                        <body name="left_wrist_yaw_link" pos="0.026025 0.030996 0.026981">
                          <inertial pos="0.00932726 0.00247855 -0.0196166" quat="0.528225 0.503579 0.545204 0.41248" mass="0.775752" diaginertia="0.0021247 0.00196098 0.000336621"/>
                          <joint name="left_wrist_yaw_joint" pos="0 0 0" axis="0 0 1" range="-1.22173 1.22173" actuatorfrcrange="-25 25"/>
                          <geom size="0.028 0.03" pos="0 0 -0.029" type="cylinder" contype="0" conaffinity="0" group="1" density="0" rgba="0.7 0.7 0.7 1"/>
                          <geom size="0.04" pos="0 0 -0.029" rgba="0.7 0.7 0.7 1"/>
                          <geom pos="0.025 0 -0.03" quat="1 0 0 0" type="mesh" contype="0" conaffinity="0" group="1" density="0" rgba="0.4 0.4 0.4 1" mesh="left_rubber_hand"/>
                        </body>
                      </body>
                    </body>
                  </body>
                </body>
              </body>
            </body>
            <body name="right_shoulder_pitch_link" pos="0.0015 -0.1125 0.35812" quat="0.990959 -0.134164 0 0">
              <inertial pos="0.00296153 -0.0520268 -0.025045" quat="0.955852 -0.291379 -0.0379149 -0.00289698" mass="1.06056" diaginertia="0.00122192 0.00110581 0.000458835"/>
              <joint name="right_shoulder_pitch_joint" pos="0 0 0" axis="0 1 0" range="-2.61799 1.8326" actuatorfrcrange="-120 120"/>
              <geom type="mesh" contype="0" conaffinity="0" group="1" density="0" rgba="0.7 0.7 0.7 1" mesh="right_shoulder_pitch_link"/>
              <geom type="mesh" rgba="0.7 0.7 0.7 1" mesh="right_shoulder_pitch_link"/>
              <body name="right_shoulder_roll_link" pos="0.027682 -0.061638 -0.039909" quat="0.990959 0.134164 0 0">
                <inertial pos="-0.02061 -0.00415443 -0.0629422" quat="0.722138 0.0778018 0.110828 0.678366" mass="1.34511" diaginertia="0.00210225 0.00198513 0.00105666"/>
                <joint name="right_shoulder_roll_joint" pos="0 0 0" axis="1 0 0" range="-2.63545 0.516617" actuatorfrcrange="-54 54"/>
                <geom type="mesh" contype="0" conaffinity="0" group="1" density="0" rgba="0.7 0.7 0.7 1" mesh="right_shoulder_roll_link"/>
                <geom type="mesh" rgba="0.7 0.7 0.7 1" mesh="right_shoulder_roll_link"/>
                <body name="right_shoulder_yaw_link" pos="-0.030632 -0.0037809 -0.10422">
                  <inertial pos="0.00364187 -0.0186515 -0.0558555" quat="0.995617 0.0729116 -0.0584518 0.00371547" mass="0.915717" diaginertia="0.00306267 0.00257349 0.00143042"/>
                  <joint name="right_shoulder_yaw_joint" pos="0 0 0" axis="0 0 1" range="-2.61799 2.61799" actuatorfrcrange="-54 54"/>
                  <geom type="mesh" contype="0" conaffinity="0" group="1" density="0" rgba="0.7 0.7 0.7 1" mesh="right_shoulder_yaw_link"/>
                  <geom type="mesh" rgba="0.7 0.7 0.7 1" mesh="right_shoulder_yaw_link"/>
                  <body name="right_elbow_link" pos="0.016955 -0.031006 -0.12719">
                    <inertial pos="0.0459969 0.0283296 -0.00661325" quat="0.463074 0.507638 0.507229 0.520177" mass="1.69432" diaginertia="0.00548751 0.00533836 0.000695052"/>
                    <joint name="right_elbow_joint" pos="0 0 0" axis="0 1 0" range="-0.986111 3.07178" actuatorfrcrange="-54 54"/>
                    <geom type="mesh" contype="0" conaffinity="0" group="1" density="0" rgba="0.7 0.7 0.7 1" mesh="right_elbow_link"/>
                    <geom type="mesh" rgba="0.7 0.7 0.7 1" mesh="right_elbow_link"/>
                    <body name="right_wrist_roll_link" pos="0.12826 0.030815 -0.013299">
                      <inertial pos="0.0337195 -0.00237482 0.00031544" quat="0.242945 0.638599 -0.286806 0.671499" mass="0.969837" diaginertia="0.000926999 0.000903832 0.000852829"/>
                      <joint name="right_wrist_roll_joint" pos="0 0 0" axis="1 0 0" range="-2.61799 2.61799" actuatorfrcrange="-54 54"/>
                      <geom type="mesh" contype="0" conaffinity="0" group="1" density="0" rgba="0.7 0.7 0.7 1" mesh="right_wrist_roll_link"/>
                      <body name="right_wrist_pitch_link" pos="0.082003 0.031003 0.00020786">
                        <inertial pos="0.01821 -0.0314035 0.0115687" quat="0.977698 0.037912 -0.203807 -0.033629" mass="0.946953" diaginertia="0.000918192 0.00082104 0.000648419"/>
                        <joint name="right_wrist_pitch_joint" pos="0 0 0" axis="0 1 0" range="-0.436332 0.436332" actuatorfrcrange="-25 25"/>
                        <geom type="mesh" contype="0" conaffinity="0" group="1" density="0" rgba="0.7 0.7 0.7 1" mesh="right_wrist_pitch_link"/>
                        <body name="right_wrist_yaw_link" pos="0.026025 -0.030996 0.026981">
                          <inertial pos="0.00932726 -0.00247855 -0.0196166" quat="0.41248 0.545204 0.503579 0.528225" mass="0.775752" diaginertia="0.0021247 0.00196098 0.000336621"/>
                          <joint name="right_wrist_yaw_joint" pos="0 0 0" axis="0 0 1" range="-1.22173 1.22173" actuatorfrcrange="-25 25"/>
                          <geom size="0.028 0.03" pos="0 0 -0.029" type="cylinder" contype="0" conaffinity="0" group="1" density="0" rgba="0.7 0.7 0.7 1"/>
                          <geom size="0.04" pos="0 0 -0.029" rgba="0.7 0.7 0.7 1"/>
                          <geom pos="0.025 0 -0.03" quat="1 0 0 0" type="mesh" contype="0" conaffinity="0" group="1" density="0" rgba="0.4 0.4 0.4 1" mesh="right_rubber_hand"/>
                        </body>
                      </body>
                    </body>
                  </body>
                </body>
              </body>
            </body>
          </body>
        </body>
      </body>
    </body>
  </worldbody>


  <actuator>
    <motor name="left_hip_pitch" joint="left_hip_pitch_joint" gear="1"/>
    <motor name="left_hip_roll" joint="left_hip_roll_joint" gear="1"/>
    <motor name="left_hip_yaw" joint="left_hip_yaw_joint" gear="1"/>
    <motor name="left_knee" joint="left_knee_joint" gear="1"/>
    <motor name="left_ankle_roll" joint="left_ankle_roll_joint" gear="1"/>
    <motor name="left_ankle_pitch" joint="left_ankle_pitch_joint" gear="1"/>

    <motor name="right_hip_pitch" joint="right_hip_pitch_joint" gear="1"/>
    <motor name="right_hip_roll" joint="right_hip_roll_joint" gear="1"/>
    <motor name="right_hip_yaw" joint="right_hip_yaw_joint" gear="1"/>
    <motor name="right_knee" joint="right_knee_joint" gear="1"/>
    <motor name="right_ankle_roll" joint="right_ankle_roll_joint" gear="1"/>
    <motor name="right_ankle_pitch" joint="right_ankle_pitch_joint" gear="1"/>

    <motor name="waist_yaw" joint="waist_yaw_joint" gear="1"/>
    <motor name="waist_roll" joint="waist_roll_joint" gear="1"/>
    <motor name="waist_pitch" joint="waist_pitch_joint" gear="1"/>

    <motor name="head_pitch" joint="head_pitch_joint" gear="1"/>
    <motor name="head_yaw" joint="head_yaw_joint" gear="1"/>

    <motor name="left_shoulder_pitch" joint="left_shoulder_pitch_joint" gear="1"/>
    <motor name="left_shoulder_roll" joint="left_shoulder_roll_joint" gear="1"/>
    <motor name="left_shoulder_yaw" joint="left_shoulder_yaw_joint" gear="1"/>
    <motor name="left_elbow" joint="left_elbow_joint" gear="1"/>
    <motor name="left_wrist_roll" joint="left_wrist_roll_joint" gear="1"/>
    <motor name="left_wrist_pitch" joint="left_wrist_pitch_joint" gear="1"/>
    <motor name="left_wrist_yaw" joint="left_wrist_yaw_joint" gear="1"/>

    <motor name="right_shoulder_pitch" joint="right_shoulder_pitch_joint" gear="1"/>
    <motor name="right_shoulder_roll" joint="right_shoulder_roll_joint" gear="1"/>
    <motor name="right_shoulder_yaw" joint="right_shoulder_yaw_joint" gear="1"/>
    <motor name="right_elbow" joint="right_elbow_joint" gear="1"/>
    <motor name="right_wrist_roll" joint="right_wrist_roll_joint" gear="1"/>
    <motor name="right_wrist_pitch" joint="right_wrist_pitch_joint" gear="1"/>
    <motor name="right_wrist_yaw" joint="right_wrist_yaw_joint" gear="1"/>
  </actuator>
</mujoco>
